<mujoco model="cafe_scene">
  <compiler angle="degree" coordinate="local" meshdir="assets"/>

  <option timestep="0.002" gravity="0 0 -9.81" integrator="RK4"/>

  <size njmax="6000" nconmax="1500"/>

  <visual>
    <headlight ambient="0.25 0.25 0.25" diffuse="0.8 0.8 0.8" specular="0.2 0.2 0.2"/>
    <rgba haze="0.12 0.12 0.12 1"/>
    <quality shadowsize="4096"/>
  </visual>

  <default>
    <!-- ��΢ƫ����ʵ���ĽӴ����������β���̫�� -->
    <geom friction="1.0 0.01 0.0005" solref="0.015 1" solimp="0.95 0.99 0.001" condim="4"/>
    <default class="panda">
      <material specular="0.5" shininess="0.25"/>
      <joint armature="0.1" damping="1" axis="0 0 1" range="-2.8973 2.8973"/>
      <general dyntype="none" biastype="affine" ctrlrange="-2.8973 2.8973" forcerange="-87 87"/>
      <default class="finger">
        <joint axis="0 1 0" type="slide" range="0 0.04"/>
      </default>

      <default class="visual">
        <geom type="mesh" contype="0" conaffinity="0" group="2"/>
      </default>
      <default class="collision">
        <geom type="mesh" group="3"/>
        <default class="fingertip_pad_collision_1">
          <geom type="box" size="0.0085 0.004 0.0085" pos="0 0.0055 0.0445"/>
        </default>
        <default class="fingertip_pad_collision_2">
          <geom type="box" size="0.003 0.002 0.003" pos="0.0055 0.002 0.05"/>
        </default>
        <default class="fingertip_pad_collision_3">
          <geom type="box" size="0.003 0.002 0.003" pos="-0.0055 0.002 0.05"/>
        </default>
        <default class="fingertip_pad_collision_4">
          <geom type="box" size="0.003 0.002 0.0035" pos="0.0055 0.002 0.0395"/>
        </default>
        <default class="fingertip_pad_collision_5">
          <geom type="box" size="0.003 0.002 0.0035" pos="-0.0055 0.002 0.0395"/>
        </default>
      </default>
    </default>
  </default>


  <asset>
    <!-- ��ɫ/���ʣ���������� -->
    <material name="mat_floor" rgba="0.76 0.56 0.34 1" reflectance="0.12"/>
    <material name="mat_wall"  rgba="0.97 0.97 0.97 1" reflectance="0.02"/>
    <material name="mat_wood"  rgba="0.45 0.30 0.20 1" reflectance="0.08"/>
    <material name="mat_metal" rgba="0.60 0.60 0.62 1" reflectance="0.25"/>
    <material name="mat_table" rgba="0.92 0.89 0.84 1" reflectance="0.07"/>
    <material name="mat_tile_green" rgba="0.20 0.45 0.32 1" reflectance="0.05"/>
    <material name="mat_glass" rgba="0.70 0.85 0.95 0.2" reflectance="0.02"/>
    <material name="mat_light" rgba="0.98 0.96 0.90 1" reflectance="0.1"/>

    <material name="mat_cup1" rgba="0.85 0.25 0.25 1"/>
    <material name="mat_cup2" rgba="0.25 0.70 0.35 1"/>
    <material name="mat_cup3" rgba="0.25 0.45 0.85 1"/>

    <material class="panda" name="white" rgba="1 1 1 1"/>
    <material class="panda" name="off_white" rgba="0.901961 0.921569 0.929412 1"/>
    <material class="panda" name="black" rgba="0.25 0.25 0.25 1"/>
    <material class="panda" name="green" rgba="0 1 0 1"/>
    <material class="panda" name="light_blue" rgba="0.039216 0.541176 0.780392 1"/>

    <!-- Collision meshes -->
    <mesh name="link0_c" file="link0.stl"/>
    <mesh name="link1_c" file="link1.stl"/>
    <mesh name="link2_c" file="link2.stl"/>
    <mesh name="link3_c" file="link3.stl"/>
    <mesh name="link4_c" file="link4.stl"/>
    <mesh name="link5_c0" file="link5_collision_0.obj"/>
    <mesh name="link5_c1" file="link5_collision_1.obj"/>
    <mesh name="link5_c2" file="link5_collision_2.obj"/>
    <mesh name="link6_c" file="link6.stl"/>
    <mesh name="link7_c" file="link7.stl"/>
    <mesh name="hand_c" file="hand.stl"/>

    <!-- Visual meshes -->
    <mesh file="link0_0.obj"/>
    <mesh file="link0_1.obj"/>
    <mesh file="link0_2.obj"/>
    <mesh file="link0_3.obj"/>
    <mesh file="link0_4.obj"/>
    <mesh file="link0_5.obj"/>
    <mesh file="link0_7.obj"/>
    <mesh file="link0_8.obj"/>
    <mesh file="link0_9.obj"/>
    <mesh file="link0_10.obj"/>
    <mesh file="link0_11.obj"/>
    <mesh file="link1.obj"/>
    <mesh file="link2.obj"/>
    <mesh file="link3_0.obj"/>
    <mesh file="link3_1.obj"/>
    <mesh file="link3_2.obj"/>
    <mesh file="link3_3.obj"/>
    <mesh file="link4_0.obj"/>
    <mesh file="link4_1.obj"/>
    <mesh file="link4_2.obj"/>
    <mesh file="link4_3.obj"/>
    <mesh file="link5_0.obj"/>
    <mesh file="link5_1.obj"/>
    <mesh file="link5_2.obj"/>
    <mesh file="link6_0.obj"/>
    <mesh file="link6_1.obj"/>
    <mesh file="link6_2.obj"/>
    <mesh file="link6_3.obj"/>
    <mesh file="link6_4.obj"/>
    <mesh file="link6_5.obj"/>
    <mesh file="link6_6.obj"/>
    <mesh file="link6_7.obj"/>
    <mesh file="link6_8.obj"/>
    <mesh file="link6_9.obj"/>
    <mesh file="link6_10.obj"/>
    <mesh file="link6_11.obj"/>
    <mesh file="link6_12.obj"/>
    <mesh file="link6_13.obj"/>
    <mesh file="link6_14.obj"/>
    <mesh file="link6_15.obj"/>
    <mesh file="link6_16.obj"/>
    <mesh file="link7_0.obj"/>
    <mesh file="link7_1.obj"/>
    <mesh file="link7_2.obj"/>
    <mesh file="link7_3.obj"/>
    <mesh file="link7_4.obj"/>
    <mesh file="link7_5.obj"/>
    <mesh file="link7_6.obj"/>
    <mesh file="link7_7.obj"/>
    <mesh file="hand_0.obj"/>
    <mesh file="hand_1.obj"/>
    <mesh file="hand_2.obj"/>
    <mesh file="hand_3.obj"/>
    <mesh file="hand_4.obj"/>
    <mesh file="finger_0.obj"/>
    <mesh file="finger_1.obj"/>
  </asset>


  <worldbody>
    <!-- �ƹ⣺����+���⣬������ÿ� -->
    <light name="key"  pos="6 6 4" dir="-1 -1 -0.8" diffuse="0.95 0.95 0.95" specular="0.25 0.25 0.25" castshadow="true"/>
    <light name="fill" pos="2 7 3" dir="0 -1 -0.6"  diffuse="0.35 0.35 0.38" castshadow="false"/>
    <light name="rim"  pos="9 2 3" dir="-1 0 -0.6"  diffuse="0.25 0.25 0.28" castshadow="false"/>
    <light name="pendant_bar1" pos="2.0 6.1 2.5" dir="0 0 -1" diffuse="1 0.95 0.85" specular="0.2 0.2 0.2" castshadow="true"/>
    <light name="pendant_bar2" pos="2.6 6.1 2.5" dir="0 0 -1" diffuse="1 0.95 0.85" specular="0.2 0.2 0.2" castshadow="true"/>
    <light name="pendant_bar3" pos="3.2 6.1 2.5" dir="0 0 -1" diffuse="1 0.95 0.85" specular="0.2 0.2 0.2" castshadow="true"/>
    <light name="pendant_table1" pos="5.0 4.8 2.6" dir="0 0 -1" diffuse="1 0.95 0.85" specular="0.2 0.2 0.2" castshadow="true"/>
    <light name="pendant_table2" pos="6.0 4.8 2.6" dir="0 0 -1" diffuse="1 0.95 0.85" specular="0.2 0.2 0.2" castshadow="true"/>

    <!-- ��� -->
    <camera name="overview" pos="8 7 3.2" xyaxes="-0.7 0.7 0 -0.25 -0.25 0.93"/>
    <camera name="bar_cam"  pos="3.3 7.6 1.6" xyaxes="1 0 0 0 0.35 0.94"/>

    <body name="window_right" pos="11.92 4.0 1.5">
      <geom name="window_right_glass" type="box" size="0.01 3.0 1.2" material="mat_glass" contype="0" conaffinity="0"/>
    </body>

    <body name="pendant_bar1" pos="2.0 6.1 2.6">
      <geom name="pendant_bar1_shade" type="cylinder" pos="0 0 -0.12" size="0.12 0.12" material="mat_light" contype="0" conaffinity="0"/>
      <geom name="pendant_bar1_rod" type="cylinder" pos="0 0 0.08" size="0.01 0.08" material="mat_metal" contype="0" conaffinity="0"/>
    </body>
    <body name="pendant_bar2" pos="2.6 6.1 2.6">
      <geom name="pendant_bar2_shade" type="cylinder" pos="0 0 -0.12" size="0.12 0.12" material="mat_light" contype="0" conaffinity="0"/>
      <geom name="pendant_bar2_rod" type="cylinder" pos="0 0 0.08" size="0.01 0.08" material="mat_metal" contype="0" conaffinity="0"/>
    </body>
    <body name="pendant_bar3" pos="3.2 6.1 2.6">
      <geom name="pendant_bar3_shade" type="cylinder" pos="0 0 -0.12" size="0.12 0.12" material="mat_light" contype="0" conaffinity="0"/>
      <geom name="pendant_bar3_rod" type="cylinder" pos="0 0 0.08" size="0.01 0.08" material="mat_metal" contype="0" conaffinity="0"/>
    </body>
    <body name="pendant_table1" pos="5.0 4.8 2.7">
      <geom name="pendant_table1_shade" type="cylinder" pos="0 0 -0.12" size="0.13 0.12" material="mat_light" contype="0" conaffinity="0"/>
      <geom name="pendant_table1_rod" type="cylinder" pos="0 0 0.08" size="0.01 0.08" material="mat_metal" contype="0" conaffinity="0"/>
    </body>
    <body name="pendant_table2" pos="6.0 4.8 2.7">
      <geom name="pendant_table2_shade" type="cylinder" pos="0 0 -0.12" size="0.13 0.12" material="mat_light" contype="0" conaffinity="0"/>
      <geom name="pendant_table2_rod" type="cylinder" pos="0 0 0.08" size="0.01 0.08" material="mat_metal" contype="0" conaffinity="0"/>
    </body>

    <!-- ���棨12m x 8m�� -->
    <geom name="floor" type="plane" size="12 8 0.1" material="mat_floor" contype="1" conaffinity="1"/>

    <!-- ǽ����ΧһȦ������ڣ� -->
    <!-- ��ǽ/��ǽ -->
    <geom name="wall_left"  type="box" pos="0 4 1.5"  size="0.08 4 1.5" material="mat_wall" contype="1" conaffinity="1"/>
    <geom name="wall_right" type="box" pos="12 4 1.5" size="0.08 4 1.5" material="mat_wall" contype="1" conaffinity="1"/>
    <!-- ��ǽ -->
    <geom name="wall_back"  type="box" pos="6 8 1.5"  size="6 0.08 1.5" material="mat_wall" contype="1" conaffinity="1"/>
    <!-- ǰǽ�����Σ���һ���ſڣ�y=0 ���� -->
    <geom name="wall_front_L" type="box" pos="3 0 1.5" size="3 0.08 1.5" material="mat_wall" contype="1" conaffinity="1"/>
    <geom name="wall_front_R" type="box" pos="10.5 0 1.5" size="1.5 0.08 1.5" material="mat_wall" contype="1" conaffinity="1"/>

    <!-- ��̨���� y��6.6 ���� -->
    <body name="bar" pos="2.2 6.6 0">
      <!-- ��̨���� -->
      <geom name="bar_base" type="box" pos="0 0 0.55" size="1.8 0.55 0.55" material="mat_wood" contype="1" conaffinity="1"/>
      <geom name="bar_tile" type="box" pos="0 -0.52 0.55" size="1.78 0.02 0.50" material="mat_tile_green" contype="0" conaffinity="0"/>
      <!-- ̨�� -->
      <geom name="bar_top"  type="box" pos="0 0 1.12" size="1.85 0.60 0.04" material="mat_table" contype="1" conaffinity="1"/>
      <!-- ��̨�ڲ��߽� -->
      <geom name="bar_kick" type="box" pos="-0.2 -0.35 0.15" size="1.4 0.15 0.15" material="mat_metal" contype="1" conaffinity="1"/>
    </body>

    <body name="bar_back" pos="2.2 7.55 0">
      <geom name="bar_back_base" type="box" pos="0 0 0.45" size="1.4 0.25 0.45" material="mat_wood" contype="1" conaffinity="1"/>
      <geom name="bar_back_top"  type="box" pos="0 0 0.92" size="1.45 0.28 0.04" material="mat_table" contype="1" conaffinity="1"/>
      <geom name="bar_shelf1"    type="box" pos="0 0.02 1.35" size="1.2 0.12 0.02" material="mat_wood" contype="0" conaffinity="0"/>
      <geom name="bar_shelf2"    type="box" pos="0 0.02 1.65" size="1.2 0.12 0.02" material="mat_wood" contype="0" conaffinity="0"/>
    </body>

    <!-- ���Ȼ��������壩 -->
    <body name="machine" pos="2.0 6.85 1.20">
      <geom type="box" size="0.22 0.18 0.20" material="mat_metal" contype="1" conaffinity="1"/>
      <geom type="box" pos="0 0.20 0.05" size="0.18 0.12 0.10" material="mat_metal" contype="1" conaffinity="1"/>
    </body>

    <!-- 3 ����/�ޣ���Բ�����ɵ��䡢��ץ�� -->
    <body name="cup_red" pos="2.10 6.35 1.22">
      <freejoint/>
      <geom type="cylinder" size="0.03 0.06" material="mat_cup1" density="250"/>
    </body>
    <body name="cup_green" pos="2.35 6.35 1.22">
      <freejoint/>
      <geom type="cylinder" size="0.03 0.06" material="mat_cup2" density="250"/>
    </body>
    <body name="cup_blue" pos="2.60 6.35 1.22">
      <freejoint/>
      <geom type="cylinder" size="0.03 0.06" material="mat_cup3" density="250"/>
    </body>

    <!-- ���������������� + �İ����ӣ��γɿɵ���ͨ���� -->
    <!-- Table A -->
    <body name="tableA" pos="8.6 5.6 0">
      <geom name="tableA_top" type="box" pos="0 0 0.76" size="0.55 0.45 0.04" material="mat_table" contype="1" conaffinity="1"/>
      <geom name="tableA_leg" type="cylinder" pos="0 0 0.38" size="0.05 0.38" material="mat_metal" contype="1" conaffinity="1"/>
    </body>
    <body name="chairA1" pos="8.6 4.8 0">
      <geom type="box" pos="0 0 0.25" size="0.22 0.22 0.03" material="mat_wood" contype="1" conaffinity="1"/>
      <geom type="box" pos="0 -0.18 0.55" size="0.22 0.03 0.30" material="mat_wood" contype="1" conaffinity="1"/>
      <geom type="cylinder" pos="0.17 0.17 0.13" size="0.02 0.13" material="mat_metal"/>
      <geom type="cylinder" pos="-0.17 0.17 0.13" size="0.02 0.13" material="mat_metal"/>
      <geom type="cylinder" pos="0.17 -0.17 0.13" size="0.02 0.13" material="mat_metal"/>
      <geom type="cylinder" pos="-0.17 -0.17 0.13" size="0.02 0.13" material="mat_metal"/>
    </body>
    <body name="chairA2" pos="8.6 6.4 0" quat="0 0 1 0">
      <geom type="box" pos="0 0 0.25" size="0.22 0.22 0.03" material="mat_wood" contype="1" conaffinity="1"/>
      <geom type="box" pos="0 -0.18 0.55" size="0.22 0.03 0.30" material="mat_wood" contype="1" conaffinity="1"/>
      <geom type="cylinder" pos="0.17 0.17 0.13" size="0.02 0.13" material="mat_metal"/>
      <geom type="cylinder" pos="-0.17 0.17 0.13" size="0.02 0.13" material="mat_metal"/>
      <geom type="cylinder" pos="0.17 -0.17 0.13" size="0.02 0.13" material="mat_metal"/>
      <geom type="cylinder" pos="-0.17 -0.17 0.13" size="0.02 0.13" material="mat_metal"/>
    </body>

    <!-- Table B -->
    <body name="tableB" pos="9.2 2.2 0">
      <geom name="tableB_top" type="box" pos="0 0 0.76" size="0.55 0.45 0.04" material="mat_table" contype="1" conaffinity="1"/>
      <geom name="tableB_leg" type="cylinder" pos="0 0 0.38" size="0.05 0.38" material="mat_metal" contype="1" conaffinity="1"/>
    </body>
    <body name="chairB1" pos="9.2 1.4 0">
      <geom type="box" pos="0 0 0.25" size="0.22 0.22 0.03" material="mat_wood" contype="1" conaffinity="1"/>
      <geom type="box" pos="0 -0.18 0.55" size="0.22 0.03 0.30" material="mat_wood" contype="1" conaffinity="1"/>
      <geom type="cylinder" pos="0.17 0.17 0.13" size="0.02 0.13" material="mat_metal"/>
      <geom type="cylinder" pos="-0.17 0.17 0.13" size="0.02 0.13" material="mat_metal"/>
      <geom type="cylinder" pos="0.17 -0.17 0.13" size="0.02 0.13" material="mat_metal"/>
      <geom type="cylinder" pos="-0.17 -0.17 0.13" size="0.02 0.13" material="mat_metal"/>
    </body>
    <body name="chairB2" pos="9.2 3.0 0" quat="0 0 1 0">
      <geom type="box" pos="0 0 0.25" size="0.22 0.22 0.03" material="mat_wood" contype="1" conaffinity="1"/>
      <geom type="box" pos="0 -0.18 0.55" size="0.22 0.03 0.30" material="mat_wood" contype="1" conaffinity="1"/>
      <geom type="cylinder" pos="0.17 0.17 0.13" size="0.02 0.13" material="mat_metal"/>
      <geom type="cylinder" pos="-0.17 0.17 0.13" size="0.02 0.13" material="mat_metal"/>
      <geom type="cylinder" pos="0.17 -0.17 0.13" size="0.02 0.13" material="mat_metal"/>
      <geom type="cylinder" pos="-0.17 -0.17 0.13" size="0.02 0.13" material="mat_metal"/>
    </body>

    <body name="tableC" pos="5.4 4.8 0">
      <geom name="tableC_top" type="box" pos="0 0 0.76" size="1.2 0.45 0.04" material="mat_table" contype="1" conaffinity="1"/>
      <geom name="tableC_leg1" type="cylinder" pos="-1.0 -0.35 0.38" size="0.05 0.38" material="mat_metal" contype="1" conaffinity="1"/>
      <geom name="tableC_leg2" type="cylinder" pos="1.0 -0.35 0.38" size="0.05 0.38" material="mat_metal" contype="1" conaffinity="1"/>
      <geom name="tableC_leg3" type="cylinder" pos="-1.0 0.35 0.38" size="0.05 0.38" material="mat_metal" contype="1" conaffinity="1"/>
      <geom name="tableC_leg4" type="cylinder" pos="1.0 0.35 0.38" size="0.05 0.38" material="mat_metal" contype="1" conaffinity="1"/>
    </body>
    <body name="stoolC1" pos="4.5 4.1 0">
      <geom name="stoolC1_seat" type="cylinder" pos="0 0 0.45" size="0.18 0.05" material="mat_wood" contype="1" conaffinity="1"/>
      <geom name="stoolC1_leg" type="cylinder" pos="0 0 0.22" size="0.04 0.22" material="mat_metal" contype="1" conaffinity="1"/>
    </body>
    <body name="stoolC2" pos="6.3 4.1 0">
      <geom name="stoolC2_seat" type="cylinder" pos="0 0 0.45" size="0.18 0.05" material="mat_wood" contype="1" conaffinity="1"/>
      <geom name="stoolC2_leg" type="cylinder" pos="0 0 0.22" size="0.04 0.22" material="mat_metal" contype="1" conaffinity="1"/>
    </body>
    <body name="stoolC3" pos="4.5 5.5 0">
      <geom name="stoolC3_seat" type="cylinder" pos="0 0 0.45" size="0.18 0.05" material="mat_wood" contype="1" conaffinity="1"/>
      <geom name="stoolC3_leg" type="cylinder" pos="0 0 0.22" size="0.04 0.22" material="mat_metal" contype="1" conaffinity="1"/>
    </body>
    <body name="stoolC4" pos="6.3 5.5 0">
      <geom name="stoolC4_seat" type="cylinder" pos="0 0 0.45" size="0.18 0.05" material="mat_wood" contype="1" conaffinity="1"/>
      <geom name="stoolC4_leg" type="cylinder" pos="0 0 0.22" size="0.04 0.22" material="mat_metal" contype="1" conaffinity="1"/>
    </body>

    <!-- ��ֲ��װ�Σ� -->
    <body name="plant" pos="11.0 7.2 0">
      <geom type="cylinder" pos="0 0 0.18" size="0.18 0.18" material="mat_metal" contype="1" conaffinity="1"/>
      <geom type="sphere"   pos="0 0 0.55" size="0.35" material="mat_cup2" contype="0" conaffinity="0"/>
    </body>

    <!-- ========================= -->
    <!-- �����ˣ�Franka Panda      -->
    <!-- ========================= -->
    <!-- ��Ҫ������ include panda.xml��panda.xml ��һ����Ƭ�Ρ���������� <mujoco> ���� -->
    <!-- �����˷��ڰ�̨��ࣺx��1.3, y��7.4�������������̨�ڣ��� -y�� -->
    <body name="panda_mount" pos="3.40 6.20 1.16" quat="1 0 0 0">
      <body name="link0" childclass="panda">
        <inertial mass="0.629769" pos="-0.041018 -0.00014 0.049974"
          fullinertia="0.00315 0.00388 0.004285 8.2904e-7 0.00015 8.2299e-6"/>
        <geom mesh="link0_0" material="off_white" class="visual"/>
        <geom mesh="link0_1" material="black" class="visual"/>
        <geom mesh="link0_2" material="off_white" class="visual"/>
        <geom mesh="link0_3" material="black" class="visual"/>
        <geom mesh="link0_4" material="off_white" class="visual"/>
        <geom mesh="link0_5" material="black" class="visual"/>
        <geom mesh="link0_7" material="white" class="visual"/>
        <geom mesh="link0_8" material="white" class="visual"/>
        <geom mesh="link0_9" material="black" class="visual"/>
        <geom mesh="link0_10" material="off_white" class="visual"/>
        <geom mesh="link0_11" material="white" class="visual"/>
        <geom mesh="link0_c" class="collision"/>
        <body name="link1" pos="0 0 0.333">
          <inertial mass="4.970684" pos="0.003875 0.002081 -0.04762"
            fullinertia="0.70337 0.70661 0.0091170 -0.00013900 0.0067720 0.019169"/>
          <joint name="joint1"/>
          <geom material="white" mesh="link1" class="visual"/>
          <geom mesh="link1_c" class="collision"/>
          <body name="link2" quat="1 -1 0 0">
            <inertial mass="0.646926" pos="-0.003141 -0.02872 0.003495"
              fullinertia="0.0079620 2.8110e-2 2.5995e-2 -3.925e-3 1.0254e-2 7.04e-4"/>
            <joint name="joint2" range="-1.7628 1.7628"/>
            <geom material="white" mesh="link2" class="visual"/>
            <geom mesh="link2_c" class="collision"/>
            <body name="link3" pos="0 -0.316 0" quat="1 1 0 0">
              <joint name="joint3"/>
              <inertial mass="3.228604" pos="2.7518e-2 3.9252e-2 -6.6502e-2"
                fullinertia="3.7242e-2 3.6155e-2 1.083e-2 -4.761e-3 -1.1396e-2 -1.2805e-2"/>
              <geom mesh="link3_0" material="white" class="visual"/>
              <geom mesh="link3_1" material="white" class="visual"/>
              <geom mesh="link3_2" material="white" class="visual"/>
              <geom mesh="link3_3" material="black" class="visual"/>
              <geom mesh="link3_c" class="collision"/>
              <body name="link4" pos="0.0825 0 0" quat="1 1 0 0">
                <inertial mass="3.587895" pos="-5.317e-2 1.04419e-1 2.7454e-2"
                  fullinertia="2.5853e-2 1.9552e-2 2.8323e-2 7.796e-3 -1.332e-3 8.641e-3"/>
                <joint name="joint4" range="-3.0718 -0.0698"/>
                <geom mesh="link4_0" material="white" class="visual"/>
                <geom mesh="link4_1" material="white" class="visual"/>
                <geom mesh="link4_2" material="black" class="visual"/>
                <geom mesh="link4_3" material="white" class="visual"/>
                <geom mesh="link4_c" class="collision"/>
                <body name="link5" pos="-0.0825 0.384 0" quat="1 -1 0 0">
                  <inertial mass="1.225946" pos="-1.1953e-2 4.1065e-2 -3.8437e-2"
                    fullinertia="3.5549e-2 2.9474e-2 8.627e-3 -2.117e-3 -4.037e-3 2.29e-4"/>
                  <joint name="joint5"/>
                  <geom mesh="link5_0" material="black" class="visual"/>
                  <geom mesh="link5_1" material="white" class="visual"/>
                  <geom mesh="link5_2" material="white" class="visual"/>
                  <geom mesh="link5_c0" class="collision"/>
                  <geom mesh="link5_c1" class="collision"/>
                  <geom mesh="link5_c2" class="collision"/>
                  <body name="link6" quat="1 1 0 0">
                    <inertial mass="1.666555" pos="6.0149e-2 -1.4117e-2 -1.0517e-2"
                      fullinertia="1.964e-3 4.354e-3 5.433e-3 1.09e-4 -1.158e-3 3.41e-4"/>
                    <joint name="joint6" range="-0.0175 3.7525"/>
                    <geom mesh="link6_0" material="off_white" class="visual"/>
                    <geom mesh="link6_1" material="white" class="visual"/>
                    <geom mesh="link6_2" material="black" class="visual"/>
                    <geom mesh="link6_3" material="white" class="visual"/>
                    <geom mesh="link6_4" material="white" class="visual"/>
                    <geom mesh="link6_5" material="white" class="visual"/>
                    <geom mesh="link6_6" material="white" class="visual"/>
                    <geom mesh="link6_7" material="light_blue" class="visual"/>
                    <geom mesh="link6_8" material="light_blue" class="visual"/>
                    <geom mesh="link6_9" material="black" class="visual"/>
                    <geom mesh="link6_10" material="black" class="visual"/>
                    <geom mesh="link6_11" material="white" class="visual"/>
                    <geom mesh="link6_12" material="green" class="visual"/>
                    <geom mesh="link6_13" material="white" class="visual"/>
                    <geom mesh="link6_14" material="black" class="visual"/>
                    <geom mesh="link6_15" material="black" class="visual"/>
                    <geom mesh="link6_16" material="white" class="visual"/>
                    <geom mesh="link6_c" class="collision"/>
                    <body name="link7" pos="0.088 0 0" quat="1 1 0 0">
                      <inertial mass="7.35522e-01" pos="1.0517e-2 -4.252e-3 6.1597e-2"
                        fullinertia="1.2516e-2 1.0027e-2 4.815e-3 -4.28e-4 -1.196e-3 -7.41e-4"/>
                      <joint name="joint7"/>
                      <geom mesh="link7_0" material="white" class="visual"/>
                      <geom mesh="link7_1" material="black" class="visual"/>
                      <geom mesh="link7_2" material="black" class="visual"/>
                      <geom mesh="link7_3" material="black" class="visual"/>
                      <geom mesh="link7_4" material="black" class="visual"/>
                      <geom mesh="link7_5" material="black" class="visual"/>
                      <geom mesh="link7_6" material="black" class="visual"/>
                      <geom mesh="link7_7" material="white" class="visual"/>
                      <geom mesh="link7_c" class="collision"/>
                      <body name="hand" pos="0 0 0.107" quat="0.9238795 0 0 -0.3826834">
                        <inertial mass="0.73" pos="-0.01 0 0.03" diaginertia="0.001 0.0025 0.0017"/>
                        <geom mesh="hand_0" material="off_white" class="visual"/>
                        <geom mesh="hand_1" material="black" class="visual"/>
                        <geom mesh="hand_2" material="black" class="visual"/>
                        <geom mesh="hand_3" material="white" class="visual"/>
                        <geom mesh="hand_4" material="off_white" class="visual"/>
                        <geom mesh="hand_c" class="collision"/>
                        <body name="left_finger" pos="0 0 0.0584">
                          <inertial mass="0.015" pos="0 0 0" diaginertia="2.375e-6 2.375e-6 7.5e-7"/>
                          <joint name="finger_joint1" class="finger"/>
                          <geom mesh="finger_0" material="off_white" class="visual"/>
                          <geom mesh="finger_1" material="black" class="visual"/>
                          <geom mesh="finger_0" class="collision"/>
                          <geom class="fingertip_pad_collision_1"/>
                          <geom class="fingertip_pad_collision_2"/>
                          <geom class="fingertip_pad_collision_3"/>
                          <geom class="fingertip_pad_collision_4"/>
                          <geom class="fingertip_pad_collision_5"/>
                        </body>
                        <body name="right_finger" pos="0 0 0.0584" quat="0 0 0 1">
                          <inertial mass="0.015" pos="0 0 0" diaginertia="2.375e-6 2.375e-6 7.5e-7"/>
                          <joint name="finger_joint2" class="finger"/>
                          <geom mesh="finger_0" material="off_white" class="visual"/>
                          <geom mesh="finger_1" material="black" class="visual"/>
                          <geom mesh="finger_0" class="collision"/>
                          <geom class="fingertip_pad_collision_1"/>
                          <geom class="fingertip_pad_collision_2"/>
                          <geom class="fingertip_pad_collision_3"/>
                          <geom class="fingertip_pad_collision_4"/>
                          <geom class="fingertip_pad_collision_5"/>
                        </body>
                      </body>
                    </body>
                  </body>
                </body>
              </body>
            </body>
          </body>
        </body>
      </body>
    </body>


  </worldbody>

  <tendon>
    <fixed name="split">
      <joint joint="finger_joint1" coef="0.5"/>
      <joint joint="finger_joint2" coef="0.5"/>
    </fixed>
  </tendon>

  <equality>
    <joint joint1="finger_joint1" joint2="finger_joint2" solimp="0.95 0.99 0.001" solref="0.005 1"/>
  </equality>

  <actuator>
    <general class="panda" name="actuator1" joint="joint1" gainprm="4500" biasprm="0 -4500 -450"/>
    <general class="panda" name="actuator2" joint="joint2" gainprm="4500" biasprm="0 -4500 -450"
      ctrlrange="-1.7628 1.7628"/>
    <general class="panda" name="actuator3" joint="joint3" gainprm="3500" biasprm="0 -3500 -350"/>
    <general class="panda" name="actuator4" joint="joint4" gainprm="3500" biasprm="0 -3500 -350"
      ctrlrange="-3.0718 -0.0698"/>
    <general class="panda" name="actuator5" joint="joint5" gainprm="2000" biasprm="0 -2000 -200" forcerange="-12 12"/>
    <general class="panda" name="actuator6" joint="joint6" gainprm="2000" biasprm="0 -2000 -200" forcerange="-12 12"
      ctrlrange="-0.0175 3.7525"/>
    <general class="panda" name="actuator7" joint="joint7" gainprm="2000" biasprm="0 -2000 -200" forcerange="-12 12"/>
    <!-- Remap original ctrlrange (0, 0.04) to (0, 255): 0.04 * 100 / 255 = 0.01568627451 -->
    <general class="panda" name="actuator8" tendon="split" forcerange="-100 100" ctrlrange="0 255"
      gainprm="0.01568627451 0 0" biasprm="0 -100 -10"/>
  </actuator>

  <keyframe>
    <key name="home" qpos="0 0 0 -1.57079 0 1.57079 -0.7853 0.04 0.04" ctrl="0 0 0 -1.57079 0 1.57079 -0.7853 255"/>
  </keyframe>

  <contact>
    <exclude body1="link0" body2="link1"/>
  </contact>
</mujoco>

